<?xml version="1.0" ?>
<!-- =================================================================================== -->
<!-- |    This document was autogenerated by xacro from my_robot_description/urdf/dual_dummy_arm_leap.urdf.xacro | -->
<!-- |    EDITING THIS FILE BY HAND IS NOT RECOMMENDED                                 | -->
<!-- =================================================================================== -->
<robot name="dual_dummy_arm_leap">
  <!-- use z_offset = -1 in isaac gym -->
  <!-- Base Link -->
  <link name="ra_base">
    <inertial>
      <mass value="0.001"/>
      <origin xyz="0 0 0"/>
      <inertia ixx="0.0001" ixy="0.0" ixz="0.0" iyy="0.0001" iyz="0.0" izz="0.0001"/>
    </inertial>
  </link>
  <!-- Translation X -->
  <link name="ra_TransXB">
    <inertial>
      <mass value="0.001"/>
      <origin xyz="0 0 0"/>
      <inertia ixx="0.0001" ixy="0.0" ixz="0.0" iyy="0.0001" iyz="0.0" izz="0.0001"/>
    </inertial>
  </link>
  <joint name="ra_TransXJ" type="prismatic">
    <parent link="ra_base"/>
    <child link="ra_TransXB"/>
    <axis xyz="1 0 0"/>
    <limit effort="10000000" lower="-1" upper="1" velocity="1000"/>
  </joint>
  <!-- Translation Y -->
  <link name="ra_TransYB">
    <inertial>
      <mass value="0.001"/>
      <origin xyz="0 0 0"/>
      <inertia ixx="0.0001" ixy="0.0" ixz="0.0" iyy="0.0001" iyz="0.0" izz="0.0001"/>
    </inertial>
  </link>
  <joint name="ra_TransYJ" type="prismatic">
    <parent link="ra_TransXB"/>
    <child link="ra_TransYB"/>
    <axis xyz="0 1 0"/>
    <limit effort="10000000" lower="-1" upper="1" velocity="1000"/>
  </joint>
  <!-- Translation Z -->
  <link name="ra_TransZB">
    <inertial>
      <mass value="0.001"/>
      <origin xyz="0 0 0"/>
      <inertia ixx="0.0001" ixy="0.0" ixz="0.0" iyy="0.0001" iyz="0.0" izz="0.0001"/>
    </inertial>
  </link>
  <joint name="ra_TransZJ" type="prismatic">
    <parent link="ra_TransYB"/>
    <child link="ra_TransZB"/>
    <origin xyz="0 0 0"/>
    <axis xyz="0 0 1"/>
    <limit effort="10000000" lower="-1" upper="1" velocity="1000"/>
  </joint>
  <!-- Rotation X -->
  <link name="ra_RotXB">
    <inertial>
      <mass value="0.001"/>
      <origin xyz="0 0 0"/>
      <inertia ixx="0.0001" ixy="0.0" ixz="0.0" iyy="0.0001" iyz="0.0" izz="0.0001"/>
    </inertial>
  </link>
  <joint name="ra_RotXJ" type="revolute">
    <parent link="ra_TransZB"/>
    <child link="ra_RotXB"/>
    <axis xyz="1 0 0"/>
    <limit effort="10000000" lower="-6.283" upper="6.283" velocity="1000"/>
  </joint>
  <!-- Rotation Y -->
  <link name="ra_RotYB">
    <inertial>
      <mass value="0.001"/>
      <origin xyz="0 0 0"/>
      <inertia ixx="0.0001" ixy="0.0" ixz="0.0" iyy="0.0001" iyz="0.0" izz="0.0001"/>
    </inertial>
  </link>
  <joint name="ra_RotYJ" type="revolute">
    <parent link="ra_RotXB"/>
    <child link="ra_RotYB"/>
    <axis xyz="0 1 0"/>
    <limit effort="10000000" lower="-6.283" upper="6.283" velocity="1000"/>
  </joint>
  <!-- Rotation Z -->
  <link name="ra_RotZB">
    <inertial>
      <mass value="0.001"/>
      <origin xyz="0 0 0"/>
      <inertia ixx="0.0001" ixy="0.0" ixz="0.0" iyy="0.0001" iyz="0.0" izz="0.0001"/>
    </inertial>
  </link>
  <joint name="ra_RotZJ" type="revolute">
    <parent link="ra_RotYB"/>
    <child link="ra_RotZB"/>
    <axis xyz="0 0 1"/>
    <limit effort="10000000" lower="-6.283" upper="6.283" velocity="1000"/>
  </joint>
  <!-- use z_offset = -1 in isaac gym -->
  <!-- Base Link -->
  <link name="la_base">
    <inertial>
      <mass value="0.001"/>
      <origin xyz="0 0 0"/>
      <inertia ixx="0.0001" ixy="0.0" ixz="0.0" iyy="0.0001" iyz="0.0" izz="0.0001"/>
    </inertial>
  </link>
  <!-- Translation X -->
  <link name="la_TransXB">
    <inertial>
      <mass value="0.001"/>
      <origin xyz="0 0 0"/>
      <inertia ixx="0.0001" ixy="0.0" ixz="0.0" iyy="0.0001" iyz="0.0" izz="0.0001"/>
    </inertial>
  </link>
  <joint name="la_TransXJ" type="prismatic">
    <parent link="la_base"/>
    <child link="la_TransXB"/>
    <axis xyz="1 0 0"/>
    <limit effort="10000000" lower="-1" upper="1" velocity="1000"/>
  </joint>
  <!-- Translation Y -->
  <link name="la_TransYB">
    <inertial>
      <mass value="0.001"/>
      <origin xyz="0 0 0"/>
      <inertia ixx="0.0001" ixy="0.0" ixz="0.0" iyy="0.0001" iyz="0.0" izz="0.0001"/>
    </inertial>
  </link>
  <joint name="la_TransYJ" type="prismatic">
    <parent link="la_TransXB"/>
    <child link="la_TransYB"/>
    <axis xyz="0 1 0"/>
    <limit effort="10000000" lower="-1" upper="1" velocity="1000"/>
  </joint>
  <!-- Translation Z -->
  <link name="la_TransZB">
    <inertial>
      <mass value="0.001"/>
      <origin xyz="0 0 0"/>
      <inertia ixx="0.0001" ixy="0.0" ixz="0.0" iyy="0.0001" iyz="0.0" izz="0.0001"/>
    </inertial>
  </link>
  <joint name="la_TransZJ" type="prismatic">
    <parent link="la_TransYB"/>
    <child link="la_TransZB"/>
    <origin xyz="0 0 0"/>
    <axis xyz="0 0 1"/>
    <limit effort="10000000" lower="-1" upper="1" velocity="1000"/>
  </joint>
  <!-- Rotation X -->
  <link name="la_RotXB">
    <inertial>
      <mass value="0.001"/>
      <origin xyz="0 0 0"/>
      <inertia ixx="0.0001" ixy="0.0" ixz="0.0" iyy="0.0001" iyz="0.0" izz="0.0001"/>
    </inertial>
  </link>
  <joint name="la_RotXJ" type="revolute">
    <parent link="la_TransZB"/>
    <child link="la_RotXB"/>
    <axis xyz="1 0 0"/>
    <limit effort="10000000" lower="-6.283" upper="6.283" velocity="1000"/>
  </joint>
  <!-- Rotation Y -->
  <link name="la_RotYB">
    <inertial>
      <mass value="0.001"/>
      <origin xyz="0 0 0"/>
      <inertia ixx="0.0001" ixy="0.0" ixz="0.0" iyy="0.0001" iyz="0.0" izz="0.0001"/>
    </inertial>
  </link>
  <joint name="la_RotYJ" type="revolute">
    <parent link="la_RotXB"/>
    <child link="la_RotYB"/>
    <axis xyz="0 1 0"/>
    <limit effort="10000000" lower="-6.283" upper="6.283" velocity="1000"/>
  </joint>
  <!-- Rotation Z -->
  <link name="la_RotZB">
    <inertial>
      <mass value="0.001"/>
      <origin xyz="0 0 0"/>
      <inertia ixx="0.0001" ixy="0.0" ixz="0.0" iyy="0.0001" iyz="0.0" izz="0.0001"/>
    </inertial>
  </link>
  <joint name="la_RotZJ" type="revolute">
    <parent link="la_RotYB"/>
    <child link="la_RotZB"/>
    <axis xyz="0 0 1"/>
    <limit effort="10000000" lower="-6.283" upper="6.283" velocity="1000"/>
  </joint>
  <link name="rh_palm_lower">
    <visual>
      <origin rpy="0 -0 0" xyz="-0.020095249652862544332 0.025757756134899473244 -0.034722403578460216134"/>
      <geometry>
        <mesh filename="./meshes/palm_lower.stl"/>
      </geometry>
      <material name="palm_lower_material">
        <color rgba="0.60392156862745094426 0.14901960784313725283 0.14901960784313725283 1.0"/>
      </material>
    </visual>
    <collision>
      <origin rpy="0 -0 0" xyz="-0.020095249652862544332 0.025757756134899473244 -0.034722403578460216134"/>
      <geometry>
        <mesh filename="./meshes/palm_lower.stl"/>
      </geometry>
    </collision>
    <inertial>
      <origin rpy="0 0 0" xyz="0 0 0"/>
      <mass value="0.237"/>
      <inertia ixx="0.000354094" ixy="-0.000001193" ixz="-0.000002445" iyy="0.000260915" iyz="-0.000002905" izz="0.000529257"/>
    </inertial>
  </link>
  <link name="rh_mcp_joint">
    <visual>
      <origin rpy="1.6375789613220999807e-15 -1.0210473302491019535e-30 1.7177968783327987474e-31" xyz="0.0084069022611744960438 0.0077662438597169954416 0.014657354985032912051"/>
      <geometry>
        <mesh filename="./meshes/mcp_joint.stl"/>
      </geometry>
      <material name="mcp_joint_material">
        <color rgba="0.86666666666666669627 0.86666666666666669627 0.050980392156862744391 1.0"/>
      </material>
    </visual>
    <collision>
      <origin rpy="1.6375789613220999807e-15 -1.0210473302491019535e-30 1.7177968783327987474e-31" xyz="0.0084069022611744960438 0.0077662438597169954416 0.014657354985032912051"/>
      <geometry>
        <mesh filename="./meshes/mcp_joint.stl"/>
      </geometry>
    </collision>
    <inertial>
      <origin rpy="0 0 0" xyz="0 0 0"/>
      <mass value="0.044"/>
      <inertia ixx="0.000011499" ixy="0.000003049" ixz="0.000000121" iyy="0.000007796" iyz="0.000000112" izz="0.000014759"/>
    </inertial>
  </link>
  <link name="rh_pip">
    <visual>
      <origin rpy="-1.570796326794896558 -1.570796326794896336 0" xyz="0.0096433630922713280131 0.00029999999999998951117 0.00078403401041737645627"/>
      <geometry>
        <mesh filename="./meshes/pip.stl"/>
      </geometry>
      <material name="pip_material">
        <color rgba="0.74901960784313725839 0.74901960784313725839 0.74901960784313725839 1.0"/>
      </material>
    </visual>
    <collision>
      <origin rpy="-1.570796326794896558 -1.570796326794896336 0" xyz="0.0096433630922713280131 0.00029999999999998951117 0.00078403401041737645627"/>
      <geometry>
        <mesh filename="./meshes/pip.stl"/>
      </geometry>
    </collision>
    <inertial>
      <origin rpy="0 0 0" xyz="0 0 0"/>
      <mass value="0.032"/>
      <inertia ixx="0.000004798" ixy="0.000000012" ixz="0.000000004" iyy="0.000002862" iyz="0.000000011" izz="0.000004234"/>
    </inertial>
  </link>
  <link name="rh_dip">
    <visual>
      <origin rpy="-3.141592653589793116 4.5075111242164408299e-32 4.4395481053923607589e-32" xyz="0.021133352895225002849 -0.0084321191467048792201 0.0097850881620952408213"/>
      <geometry>
        <mesh filename="./meshes/dip.stl"/>
      </geometry>
      <material name="dip_material">
        <color rgba="0.86666666666666669627 0.86666666666666669627 0.050980392156862744391 1.0"/>
      </material>
    </visual>
    <collision>
      <origin rpy="-3.141592653589793116 4.5075111242164408299e-32 4.4395481053923607589e-32" xyz="0.021133352895225002849 -0.0084321191467048792201 0.0097850881620952408213"/>
      <geometry>
        <mesh filename="./meshes/dip.stl"/>
      </geometry>
    </collision>
    <inertial>
      <origin rpy="0 0 0" xyz="0 0 0"/>
      <mass value="0.037"/>
      <inertia ixx="0.000005542" ixy="-0.000000607" ixz="-0.000000017" iyy="0.000005727" iyz="-0.000000023" izz="0.000006682"/>
    </inertial>
  </link>
  <link name="rh_fingertip_base">
    <visual>
      <origin rpy="3.141592653589793116 1.1993117970061734707e-33 4.4395481053923607589e-32" xyz="0.013286424108533503169 -0.0061142383865419869249 0.014499999999999497666"/>
      <geometry>
        <mesh filename="./meshes/fingertip_base.stl"/>
      </geometry>
      <material name="fingertip_material">
        <color rgba="0.86666666666666669627 0.86666666666666669627 0.050980392156862744391 1.0"/>
      </material>
    </visual>
    <collision>
      <origin rpy="3.141592653589793116 1.1993117970061734707e-33 4.4395481053923607589e-32" xyz="0.013286424108533503169 -0.0061142383865419869249 0.014499999999999497666"/>
      <geometry>
        <mesh filename="./meshes/fingertip_base.stl"/>
      </geometry>
    </collision>
    <inertial>
      <origin rpy="0 0 0" xyz="0 0 0"/>
      <mass value="0.016"/>
      <inertia ixx="0.000003368" ixy="0.000000115" ixz="0" iyy="0.000001556" iyz="0" izz="0.000002863"/>
    </inertial>
  </link>
  <joint name="rh_joint_0" type="revolute">
    <origin rpy="-1.570796326794896558 -1.0065212660796336576e-15 1.5707963267948943376" xyz="-0.012200000000000007713 0.038099999999999994982 0.014500000000000000736"/>
    <parent link="rh_mcp_joint"/>
    <child link="rh_pip"/>
    <axis xyz="0 0 -1"/>
    <limit effort="0.95" lower="-1.047" upper="1.047" velocity="8.48"/>
    <joint_properties friction="0.0"/>
    <dynamics D="1" K="7000" damping="0.003" friction="0.0" mu_coulomb="0" mu_viscous="16"/>
  </joint>
  <joint name="rh_joint_1" type="revolute">
    <origin rpy="1.5707963267948950037 1.5707963267948945596 0" xyz="-0.0070952496528625457958 0.023057756134899472233 -0.01872240357846021927"/>
    <parent link="rh_palm_lower"/>
    <child link="rh_mcp_joint"/>
    <axis xyz="0 0 -1"/>
    <limit effort="0.95" lower="-0.314" upper="2.23" velocity="8.48"/>
    <joint_properties friction="0.0"/>
  </joint>
  <joint name="rh_joint_2" type="revolute">
    <origin rpy="1.5707963267948958919 -1.570796326794896336 0" xyz="0.01499999999999996822 0.014299999999999904801 -0.012999999999999824196"/>
    <parent link="rh_pip"/>
    <child link="rh_dip"/>
    <axis xyz="0 0 -1"/>
    <limit effort="0.95" lower="-0.506" upper="1.885" velocity="8.48"/>
    <joint_properties friction="0.0"/>
  </joint>
  <joint name="rh_joint_3" type="revolute">
    <origin rpy="4.5935029425113685044e-17 -2.8730071914463794583e-16 4.4395481053923607589e-32" xyz="-4.0880582495572692636e-09 -0.036100004210367367397 0.00020000000000007858714"/>
    <parent link="rh_dip"/>
    <child link="rh_fingertip_base"/>
    <axis xyz="0 0 -1"/>
    <limit effort="0.95" lower="-0.366" upper="2.042" velocity="8.48"/>
    <joint_properties friction="0.0"/>
  </joint>
  <link name="rh_mcp_joint_2">
    <visual>
      <origin rpy="1.6375789613220999807e-15 -1.0076465469034000467e-30 2.1209300131419907151e-61" xyz="0.0084069022611744960438 0.0077662438597169954416 0.014657354985032913786"/>
      <geometry>
        <mesh filename="./meshes/mcp_joint.stl"/>
      </geometry>
      <material name="mcp_joint_material">
        <color rgba="0.86666666666666669627 0.86666666666666669627 0.050980392156862744391 1.0"/>
      </material>
    </visual>
    <collision>
      <origin rpy="1.6375789613220999807e-15 -1.0076465469034000467e-30 2.1209300131419907151e-61" xyz="0.0084069022611744960438 0.0077662438597169954416 0.014657354985032913786"/>
      <geometry>
        <mesh filename="./meshes/mcp_joint.stl"/>
      </geometry>
    </collision>
    <inertial>
      <origin rpy="0 0 0" xyz="0 0 0"/>
      <mass value="0.044"/>
      <inertia ixx="0.000011499" ixy="0.000003049" ixz="0.000000121" iyy="0.000007796" iyz="0.000000112" izz="0.000014759"/>
    </inertial>
  </link>
  <link name="rh_pip_2">
    <visual>
      <origin rpy="-1.570796326794896558 -1.570796326794896336 0" xyz="0.0096433630922713280131 0.00029999999999999471534 0.00078403401041737645627"/>
      <geometry>
        <mesh filename="./meshes/pip.stl"/>
      </geometry>
      <material name="pip_material">
        <color rgba="0.74901960784313725839 0.74901960784313725839 0.74901960784313725839 1.0"/>
      </material>
    </visual>
    <collision>
      <origin rpy="-1.570796326794896558 -1.570796326794896336 0" xyz="0.0096433630922713280131 0.00029999999999999471534 0.00078403401041737645627"/>
      <geometry>
        <mesh filename="./meshes/pip.stl"/>
      </geometry>
    </collision>
    <inertial>
      <origin rpy="0 0 0" xyz="0 0 0"/>
      <mass value="0.032"/>
      <inertia ixx="0.000004798" ixy="0.000000012" ixz="0.000000004" iyy="0.000002862" iyz="0.000000011" izz="0.000004234"/>
    </inertial>
  </link>
  <link name="rh_dip_2">
    <visual>
      <origin rpy="-3.141592653589793116 2.1146933785271955805e-32 1.4408183216511868558e-31" xyz="0.021133352895225002849 -0.0084321191467048653423 0.0097850881620952373519"/>
      <geometry>
        <mesh filename="./meshes/dip.stl"/>
      </geometry>
      <material name="dip_material">
        <color rgba="0.86666666666666669627 0.86666666666666669627 0.050980392156862744391 1.0"/>
      </material>
    </visual>
    <collision>
      <origin rpy="-3.141592653589793116 2.1146933785271955805e-32 1.4408183216511868558e-31" xyz="0.021133352895225002849 -0.0084321191467048653423 0.0097850881620952373519"/>
      <geometry>
        <mesh filename="./meshes/dip.stl"/>
      </geometry>
    </collision>
    <inertial>
      <origin rpy="0 0 0" xyz="0 0 0"/>
      <mass value="0.037"/>
      <inertia ixx="0.000005542" ixy="-0.000000607" ixz="-0.000000017" iyy="0.000005727" iyz="-0.000000023" izz="0.000006682"/>
    </inertial>
  </link>
  <link name="rh_fingertip_base_2">
    <visual>
      <origin rpy="3.141592653589793116 1.1993117970061734707e-33 4.4395481053923607589e-32" xyz="0.013286424108533503169 -0.0061142383865419869249 0.014499999999999497666"/>
      <geometry>
        <mesh filename="./meshes/fingertip_base.stl"/>
      </geometry>
      <material name="fingertip_material">
        <color rgba="0.86666666666666669627 0.86666666666666669627 0.050980392156862744391 1.0"/>
      </material>
    </visual>
    <collision>
      <origin rpy="3.141592653589793116 1.1993117970061734707e-33 4.4395481053923607589e-32" xyz="0.013286424108533503169 -0.0061142383865419869249 0.014499999999999497666"/>
      <geometry>
        <mesh filename="./meshes/fingertip_base.stl"/>
      </geometry>
    </collision>
    <inertial>
      <origin rpy="0 0 0" xyz="0 0 0"/>
      <mass value="0.016"/>
      <inertia ixx="0.000003368" ixy="0.000000115" ixz="0" iyy="0.000001556" iyz="0" izz="0.000002863"/>
    </inertial>
  </link>
  <joint name="rh_joint_4" type="revolute">
    <origin rpy="-1.570796326794896558 -1.0065212760057939085e-15 1.5707963267948943376" xyz="-0.012200000000000019856 0.038099999999999981104 0.01450000000000000594"/>
    <parent link="rh_mcp_joint_2"/>
    <child link="rh_pip_2"/>
    <axis xyz="0 0 -1"/>
    <limit effort="0.95" lower="-1.047" upper="1.047" velocity="8.48"/>
    <joint_properties friction="0.0"/>
  </joint>
  <joint name="rh_joint_5" type="revolute">
    <origin rpy="1.570796326794896558 1.570796326794896558 0" xyz="-0.0070952496528625388569 -0.022392243865100525113 -0.018722403578460229678"/>
    <parent link="rh_palm_lower"/>
    <child link="rh_mcp_joint_2"/>
    <axis xyz="0 0 -1"/>
    <limit effort="0.95" lower="-0.314" upper="2.23" velocity="8.48"/>
    <joint_properties friction="0.0"/>
  </joint>
  <joint name="rh_joint_6" type="revolute">
    <origin rpy="1.5707963267948958919 -1.570796326794896336 0" xyz="0.014999999999999975159 0.014300000000000000211 -0.013000000000000018485"/>
    <parent link="rh_pip_2"/>
    <child link="rh_dip_2"/>
    <axis xyz="0 0 -1"/>
    <limit effort="0.95" lower="-0.506" upper="1.885" velocity="8.48"/>
    <joint_properties friction="0.0"/>
  </joint>
  <joint name="rh_joint_7" type="revolute">
    <origin rpy="4.5935029425113654229e-17 -2.8730071914463794583e-16 1.4408183216511868558e-31" xyz="1.0061396160665481148e-16 -0.036099999999999854428 0.00020000000000007858714"/>
    <parent link="rh_dip_2"/>
    <child link="rh_fingertip_base_2"/>
    <axis xyz="0 0 -1"/>
    <limit effort="0.95" lower="-0.366" upper="2.042" velocity="8.48"/>
    <joint_properties friction="0.0"/>
  </joint>
  <link name="rh_mcp_joint_3">
    <visual>
      <origin rpy="1.6375789613220999807e-15 -1.0059504988632626953e-30 5.729641584552035421e-32" xyz="0.0084069022611744995133 0.0077662438597169963089 0.014657354985032913786"/>
      <geometry>
        <mesh filename="./meshes/mcp_joint.stl"/>
      </geometry>
      <material name="mcp_joint_material">
        <color rgba="0.86666666666666669627 0.86666666666666669627 0.050980392156862744391 1.0"/>
      </material>
    </visual>
    <collision>
      <origin rpy="1.6375789613220999807e-15 -1.0059504988632626953e-30 5.729641584552035421e-32" xyz="0.0084069022611744995133 0.0077662438597169963089 0.014657354985032913786"/>
      <geometry>
        <mesh filename="./meshes/mcp_joint.stl"/>
      </geometry>
    </collision>
    <inertial>
      <origin rpy="0 0 0" xyz="0 0 0"/>
      <mass value="0.044"/>
      <inertia ixx="0.000011499" ixy="0.000003049" ixz="0.000000121" iyy="0.000007796" iyz="0.000000112" izz="0.000014759"/>
    </inertial>
  </link>
  <link name="rh_pip_3">
    <visual>
      <origin rpy="-1.570796326794896558 -1.570796326794896336 0" xyz="0.0096433630922713314826 0.00029999999999998083755 0.00078403401041737645627"/>
      <geometry>
        <mesh filename="./meshes/pip.stl"/>
      </geometry>
      <material name="pip_material">
        <color rgba="0.74901960784313725839 0.74901960784313725839 0.74901960784313725839 1.0"/>
      </material>
    </visual>
    <collision>
      <origin rpy="-1.570796326794896558 -1.570796326794896336 0" xyz="0.0096433630922713314826 0.00029999999999998083755 0.00078403401041737645627"/>
      <geometry>
        <mesh filename="./meshes/pip.stl"/>
      </geometry>
    </collision>
    <inertial>
      <origin rpy="0 0 0" xyz="0 0 0"/>
      <mass value="0.032"/>
      <inertia ixx="0.000004798" ixy="0.000000012" ixz="0.000000004" iyy="0.000002862" iyz="0.000000011" izz="0.000004234"/>
    </inertial>
  </link>
  <link name="rh_dip_3">
    <visual>
      <origin rpy="-3.141592653589793116 -1.4095651113919093005e-33 1.5565411607615035382e-32" xyz="0.021133352895225006318 -0.0084321191467048653423 0.0097850881620952373519"/>
      <geometry>
        <mesh filename="./meshes/dip.stl"/>
      </geometry>
      <material name="dip_material">
        <color rgba="0.86666666666666669627 0.86666666666666669627 0.050980392156862744391 1.0"/>
      </material>
    </visual>
    <collision>
      <origin rpy="-3.141592653589793116 -1.4095651113919093005e-33 1.5565411607615035382e-32" xyz="0.021133352895225006318 -0.0084321191467048653423 0.0097850881620952373519"/>
      <geometry>
        <mesh filename="./meshes/dip.stl"/>
      </geometry>
    </collision>
    <inertial>
      <origin rpy="0 0 0" xyz="0 0 0"/>
      <mass value="0.037"/>
      <inertia ixx="0.000005542" ixy="-0.000000607" ixz="-0.000000017" iyy="0.000005727" iyz="-0.000000023" izz="0.000006682"/>
    </inertial>
  </link>
  <link name="rh_fingertip_base_3">
    <visual>
      <origin rpy="3.141592653589793116 1.1993117970061734707e-33 4.4395481053923607589e-32" xyz="0.013286424108533503169 -0.0061142383865419869249 0.014499999999999497666"/>
      <geometry>
        <mesh filename="./meshes/fingertip_base.stl"/>
      </geometry>
      <material name="fingertip_material">
        <color rgba="0.86666666666666669627 0.86666666666666669627 0.050980392156862744391 1.0"/>
      </material>
    </visual>
    <collision>
      <origin rpy="3.141592653589793116 1.1993117970061734707e-33 4.4395481053923607589e-32" xyz="0.013286424108533503169 -0.0061142383865419869249 0.014499999999999497666"/>
      <geometry>
        <mesh filename="./meshes/fingertip_base.stl"/>
      </geometry>
      <material name="fingertip_material">
        <color rgba="0.86666666666666669627 0.86666666666666669627 0.050980392156862744391 1.0"/>
      </material>
    </collision>
    <inertial>
      <origin rpy="0 0 0" xyz="0 0 0"/>
      <mass value="0.016"/>
      <inertia ixx="0.000003368" ixy="0.000000115" ixz="0" iyy="0.000001556" iyz="0" izz="0.000002863"/>
    </inertial>
  </link>
  <joint name="rh_joint_8" type="revolute">
    <origin rpy="-1.570796326794896558 -1.0065212660796360242e-15 1.5707963267948943376" xyz="-0.012200000000000004244 0.038100000000000001921 0.014499999999999999001"/>
    <parent link="rh_mcp_joint_3"/>
    <child link="rh_pip_3"/>
    <axis xyz="0 0 -1"/>
    <limit effort="0.95" lower="-1.047" upper="1.047" velocity="8.48"/>
    <joint_properties friction="0.0"/>
  </joint>
  <joint name="rh_joint_9" type="revolute">
    <origin rpy="1.5707963267948950037 1.5707963267948945596 0" xyz="-0.0070952454426398371343 -0.067842243865100515521 -0.018722407666402932774"/>
    <parent link="rh_palm_lower"/>
    <child link="rh_mcp_joint_3"/>
    <axis xyz="0 0 -1"/>
    <limit effort="0.95" lower="-0.314" upper="2.23" velocity="8.48"/>
    <joint_properties friction="0.0"/>
  </joint>
  <joint name="rh_joint_10" type="revolute">
    <origin rpy="1.5707963267948958919 -1.570796326794896336 0" xyz="0.014999999999999971689 0.014299999999999951639 -0.012999999999999959505"/>
    <parent link="rh_pip_3"/>
    <child link="rh_dip_3"/>
    <axis xyz="0 0 -1"/>
    <limit effort="0.95" lower="-0.506" upper="1.885" velocity="8.48"/>
    <joint_properties friction="0.0"/>
  </joint>
  <joint name="rh_joint_11" type="revolute">
    <origin rpy="4.5935029425113685044e-17 -2.8730071914463799514e-16 1.5565411607615035382e-32" xyz="9.7144514654701197287e-17 -0.036099999999999868305 0.00020000000000007511769"/>
    <parent link="rh_dip_3"/>
    <child link="rh_fingertip_base_3"/>
    <axis xyz="0 0 -1"/>
    <limit effort="0.95" lower="-0.366" upper="2.042" velocity="8.48"/>
    <joint_properties friction="0.0"/>
  </joint>
  <link name="rh_pip_4">
    <visual>
      <origin rpy="-1.570796326794896558 -1.570796326794896336 0" xyz="-0.0053566369077286714317 0.00029999999999999991951 0.00078403401041737819099"/>
      <geometry>
        <mesh filename="./meshes/pip.stl"/>
      </geometry>
      <material name="pip_material">
        <color rgba="0.74901960784313725839 0.74901960784313725839 0.74901960784313725839 1.0"/>
      </material>
    </visual>
    <collision>
      <origin rpy="-1.570796326794896558 -1.570796326794896336 0" xyz="-0.0053566369077286714317 0.00029999999999999991951 0.00078403401041737819099"/>
      <geometry>
        <mesh filename="./meshes/pip.stl"/>
      </geometry>
    </collision>
    <inertial>
      <origin rpy="0 0 0" xyz="0 0 0"/>
      <mass value="0.032"/>
      <inertia ixx="0.000004798" ixy="0.000000012" ixz="0.000000004" iyy="0.000002862" iyz="0.000000011" izz="0.000004234"/>
    </inertial>
  </link>
  <link name="rh_thumb_pip">
    <visual>
      <origin rpy="1.570796326794896558 1.6050198443300152637e-46 -3.9204996250525192755e-59" xyz="0.011961920770611186859 -5.3082538364890297089e-16 -0.015852648956664199681"/>
      <geometry>
        <mesh filename="./meshes/thumb_pip.stl"/>
      </geometry>
      <material name="thumb_pip_material">
        <color rgba="0.86666666666666669627 0.86666666666666669627 0.050980392156862744391 1.0"/>
      </material>
    </visual>
    <collision>
      <origin rpy="1.570796326794896558 1.6050198443300152637e-46 -3.9204996250525192755e-59" xyz="0.011961920770611186859 -5.3082538364890297089e-16 -0.015852648956664199681"/>
      <geometry>
        <mesh filename="./meshes/thumb_pip.stl"/>
      </geometry>
    </collision>
    <inertial>
      <origin rpy="0 0 0" xyz="0 0 0"/>
      <mass value="0.003"/>
      <inertia ixx="0.000000593" ixy="0" ixz="0" iyy="0.000000549" iyz="0" izz="0.000000224"/>
    </inertial>
  </link>
  <link name="rh_thumb_dip">
    <visual>
      <origin rpy="1.9428902930940098942e-16 3.2751579226442200773e-15 1.1123758529657360012e-46" xyz="0.043968715707239175439 0.057952952973709198625 -0.0086286764493694757122"/>
      <geometry>
        <mesh filename="./meshes/thumb_dip.stl"/>
      </geometry>
      <material name="thumb_dip_material">
        <color rgba="0.86666666666666669627 0.86666666666666669627 0.050980392156862744391 1.0"/>
      </material>
    </visual>
    <collision>
      <origin rpy="1.9428902930940098942e-16 3.2751579226442200773e-15 1.1123758529657360012e-46" xyz="0.043968715707239175439 0.057952952973709198625 -0.0086286764493694757122"/>
      <geometry>
        <mesh filename="./meshes/thumb_dip.stl"/>
      </geometry>
    </collision>
    <inertial>
      <origin rpy="0 0 0" xyz="0 0 0"/>
      <mass value="0.038"/>
      <inertia ixx="0.000008474" ixy="0.000000241" ixz="0.000000026" iyy="0.000003841" iyz="0.000000025" izz="0.000007679"/>
    </inertial>
  </link>
  <link name="rh_thumb_fingertip_base">
    <visual>
      <origin rpy="4.3790577010156367543e-47 -3.3306690738754701143e-16 1.2042408677791935383e-46" xyz="0.062559538462667388381 0.078459682911396988469 0.048992911807332215068"/>
      <geometry>
        <mesh filename="./meshes/thumb_fingertip_base.stl"/>
      </geometry>
      <material name="thumb_fingertip_material">
        <color rgba="0.60392156862745094426 0.14901960784313725283 0.14901960784313725283 1.0"/>
      </material>
    </visual>
    <collision>
      <origin rpy="4.3790577010156367543e-47 -3.3306690738754701143e-16 1.2042408677791935383e-46" xyz="0.062559538462667388381 0.078459682911396988469 0.048992911807332215068"/>
      <geometry>
        <mesh filename="./meshes/thumb_fingertip_base.stl"/>
      </geometry>
    </collision>
    <inertial>
      <origin rpy="0 0 0" xyz="0 0 0"/>
      <mass value="0.049"/>
      <inertia ixx="0.000020372" ixy="-0.000000489" ixz="-0.00000003" iyy="0.000004336" iyz="-0.000000097" izz="0.000019845"/>
    </inertial>
  </link>
  <joint name="rh_joint_12" type="revolute">
    <origin rpy="-8.2381766464939424156e-17 1.5707963267948956698 0" xyz="-0.069395249652862533996 -0.0012422438651005258004 -0.021622403578460215601"/>
    <parent link="rh_palm_lower"/>
    <child link="rh_pip_4"/>
    <axis xyz="0 0 -1"/>
    <limit effort="0.95" lower="-0.349" upper="2.094" velocity="8.48"/>
    <joint_properties friction="0.0"/>
  </joint>
  <joint name="rh_joint_13" type="revolute">
    <origin rpy="1.5707963267948958919 -1.570796326794896336 0" xyz="-2.7755575615628913511e-17 0.014300000000000005415 -0.013000000000000011546"/>
    <parent link="rh_pip_4"/>
    <child link="rh_thumb_pip"/>
    <axis xyz="0 0 -1"/>
    <limit effort="0.95" lower="-0.47" upper="2.443" velocity="8.48"/>
    <joint_properties friction="0.0"/>
  </joint>
  <joint name="rh_joint_14" type="revolute">
    <origin rpy="-1.570796326794896558 1.6050198443300131245e-46 -1.9721522630516624601e-31" xyz="0 0.014499999999999966041 -0.017000000000000053263"/>
    <parent link="rh_thumb_pip"/>
    <child link="rh_thumb_dip"/>
    <axis xyz="0 0 -1"/>
    <limit effort="0.95" lower="-1.20" upper="1.90" velocity="8.48"/>
    <joint_properties friction="0.0"/>
  </joint>
  <joint name="rh_joint_15" type="revolute">
    <origin rpy="1.5063958491491781023e-44 5.4234187233935260503e-31 3.141592653589793116" xyz="-1.249000902703301108e-16 0.046599999999999863753 0.00019999999999997710581"/>
    <parent link="rh_thumb_dip"/>
    <child link="rh_thumb_fingertip_base"/>
    <axis xyz="0 0 -1"/>
    <limit effort="0.95" lower="-1.34" upper="1.88" velocity="8.48"/>
    <joint_properties friction="0.0"/>
  </joint>
  <link name="rh_wrist"/>
  <joint name="rh_palm_to_wrist" type="fixed">
    <origin rpy="0 1.5707963267948966 0" xyz="-0.16 -0.04 -0.01"/>
    <parent link="rh_palm_lower"/>
    <child link="rh_wrist"/>
  </joint>
  <!-- the links and joints for customized fingertips -->
  <link name="rh_fingertip_1">
    <visual>
      <origin rpy="0 0 0" xyz="0 0 0"/>
      <geometry>
        <mesh filename="./meshes/convex_tip_v2.obj"/>
      </geometry>
      <material name="fingertip_material">
        <color rgba="0.86666666666666669627 0.86666666666666669627 0.050980392156862744391 1.0"/>
      </material>
    </visual>
    <collision>
      <origin rpy="0 0 0" xyz="0 0 0"/>
      <geometry>
        <mesh filename="./meshes/convex_tip_v2.obj"/>
      </geometry>
    </collision>
    <inertial>
      <!-- TODO(yongpeng) modify the inertia -->
      <origin rpy="0 0 0" xyz="0 0 0"/>
      <mass value="0.0000000001"/>
      <inertia ixx="0.0000000001" ixy="0" ixz="0" iyy="0.0000000001" iyz="0" izz="0.0000000001"/>
    </inertial>
  </link>
  <link name="rh_fingertip_2">
    <visual>
      <origin rpy="0 0 0" xyz="0 0 0"/>
      <geometry>
        <mesh filename="./meshes/convex_tip_v2.obj"/>
      </geometry>
      <material name="fingertip_material">
        <color rgba="0.86666666666666669627 0.86666666666666669627 0.050980392156862744391 1.0"/>
      </material>
    </visual>
    <collision>
      <origin rpy="0 0 0" xyz="0 0 0"/>
      <geometry>
        <mesh filename="./meshes/convex_tip_v2.obj"/>
      </geometry>
    </collision>
    <inertial>
      <!-- TODO(yongpeng) modify the inertia -->
      <origin rpy="0 0 0" xyz="0 0 0"/>
      <mass value="0.0000000001"/>
      <inertia ixx="0.0000000001" ixy="0" ixz="0" iyy="0.0000000001" iyz="0" izz="0.0000000001"/>
    </inertial>
  </link>
  <link name="rh_fingertip_3">
    <visual>
      <origin rpy="0 0 0" xyz="0 0 0"/>
      <geometry>
        <mesh filename="./meshes/convex_tip_v2.obj"/>
      </geometry>
      <material name="fingertip_material">
        <color rgba="0.86666666666666669627 0.86666666666666669627 0.050980392156862744391 1.0"/>
      </material>
    </visual>
    <collision>
      <origin rpy="0 0 0" xyz="0 0 0"/>
      <geometry>
        <mesh filename="./meshes/convex_tip_v2.obj"/>
      </geometry>
    </collision>
    <inertial>
      <!-- TODO(yongpeng) modify the inertia -->
      <origin rpy="0 0 0" xyz="0 0 0"/>
      <mass value="0.0000000001"/>
      <inertia ixx="0.0000000001" ixy="0" ixz="0" iyy="0.0000000001" iyz="0" izz="0.0000000001"/>
    </inertial>
  </link>
  <link name="rh_thumb_fingertip">
    <visual>
      <origin rpy="0 0 0" xyz="0 0 0"/>
      <geometry>
        <mesh filename="./meshes/convex_tip_thumb_v2.obj"/>
      </geometry>
      <material name="fingertip_material">
        <color rgba="0.86666666666666669627 0.86666666666666669627 0.050980392156862744391 1.0"/>
      </material>
    </visual>
    <collision>
      <origin rpy="0 0 0" xyz="0 0 0"/>
      <geometry>
        <mesh filename="./meshes/convex_tip_thumb_v2.obj"/>
      </geometry>
    </collision>
    <inertial>
      <origin rpy="0 0 0" xyz="0 0 0"/>
      <mass value="0.0000000001"/>
      <inertia ixx="0.0000000001" ixy="0" ixz="0" iyy="0.0000000001" iyz="0" izz="0.0000000001"/>
    </inertial>
  </link>
  <joint name="rh_finger1_tipbase2tip" type="fixed">
    <origin rpy="0 1.5707963267948966 3.141592653589793" xyz="0 -0.017 0.0145"/>
    <parent link="rh_fingertip_base"/>
    <child link="rh_fingertip_1"/>
  </joint>
  <joint name="rh_finger2_tipbase2tip" type="fixed">
    <origin rpy="0 1.5707963267948966 3.141592653589793" xyz="0 -0.017 0.0145"/>
    <parent link="rh_fingertip_base_2"/>
    <child link="rh_fingertip_2"/>
  </joint>
  <joint name="rh_finger3_tipbase2tip" type="fixed">
    <origin rpy="0 1.5707963267948966 3.141592653589793" xyz="0 -0.017 0.0145"/>
    <parent link="rh_fingertip_base_3"/>
    <child link="rh_fingertip_3"/>
  </joint>
  <joint name="rh_thumb_tipbase2tip" type="fixed">
    <origin rpy="0 1.5707963267948966 3.141592653589793" xyz="0 -0.03 -0.0145"/>
    <parent link="rh_thumb_fingertip_base"/>
    <child link="rh_thumb_fingertip"/>
  </joint>
  <!-- the links and joints for fingertip centers -->
  <link name="rh_finger1_tip_center"/>
  <link name="rh_finger2_tip_center"/>
  <link name="rh_finger3_tip_center"/>
  <link name="rh_thumb_tip_center"/>
  <joint name="rh_finger1_tip2center" type="fixed">
    <origin rpy="0 0 1.5707963267948966" xyz="0 0.025 0.01"/>
    <parent link="rh_fingertip_1"/>
    <child link="rh_finger1_tip_center"/>
  </joint>
  <joint name="rh_finger2_tip2center" type="fixed">
    <origin rpy="0 0 1.5707963267948966" xyz="0 0.025 0.01"/>
    <parent link="rh_fingertip_2"/>
    <child link="rh_finger2_tip_center"/>
  </joint>
  <joint name="rh_finger3_tip2center" type="fixed">
    <origin rpy="0 0 1.5707963267948966" xyz="0 0.025 0.01"/>
    <parent link="rh_fingertip_3"/>
    <child link="rh_finger3_tip_center"/>
  </joint>
  <joint name="rh_thumb_tip2center" type="fixed">
    <origin rpy="0 0 1.5707963267948966" xyz="0 0.0245 0.011"/>
    <parent link="rh_thumb_fingertip"/>
    <child link="rh_thumb_tip_center"/>
  </joint>
  <!-- the links and joints for fingertip centers (lower) -->
  <!-- 0.02 m is the length of human distal link -->
  <link name="rh_finger1_tip_center_lower"/>
  <link name="rh_finger2_tip_center_lower"/>
  <link name="rh_finger3_tip_center_lower"/>
  <link name="rh_thumb_tip_center_lower"/>
  <joint name="rh_finger1_tip_center2lower" type="fixed">
    <origin rpy="0 0 0" xyz="-0.02 0 0"/>
    <parent link="rh_finger1_tip_center"/>
    <child link="rh_finger1_tip_center_lower"/>
  </joint>
  <joint name="rh_finger2_tip_center2lower" type="fixed">
    <origin rpy="0 0 0" xyz="-0.02 0 0"/>
    <parent link="rh_finger2_tip_center"/>
    <child link="rh_finger2_tip_center_lower"/>
  </joint>
  <joint name="rh_finger3_tip_center2lower" type="fixed">
    <origin rpy="0 0 0" xyz="-0.02 0 0"/>
    <parent link="rh_finger3_tip_center"/>
    <child link="rh_finger3_tip_center_lower"/>
  </joint>
  <joint name="rh_thumb_tip_center2lower" type="fixed">
    <origin rpy="0 0 0" xyz="-0.02 0 0"/>
    <parent link="rh_thumb_tip_center"/>
    <child link="rh_thumb_tip_center_lower"/>
  </joint>
  <link name="lh_palm_lower_left">
    <visual>
      <origin rpy="1.57079632679489678 1.1239611599647231752e-28 3.1415926535897908956" xyz="-0.095574224938392599027 -0.11704001150113751972 0.02077960705260517571"/>
      <geometry>
        <mesh filename="./meshes/palm_lower_left.stl"/>
      </geometry>
      <material name="palm_lower_left_material">
        <color rgba="0.60392156862745094426 0.14901960784313725283 0.14901960784313725283 1.0"/>
      </material>
    </visual>
    <collision>
      <origin rpy="1.57079632679489678 1.1239611599647231752e-28 3.1415926535897908956" xyz="-0.095574224938392599027 -0.11704001150113751972 0.02077960705260517571"/>
      <geometry>
        <mesh filename="./meshes/palm_lower_left.stl"/>
      </geometry>
    </collision>
    <inertial>
      <origin rpy="0 0 0" xyz="0 0 0"/>
      <mass value="0.235"/>
      <inertia ixx="0.000351007" ixy="-0.000001393" ixz="-0.000000694" iyy="0.000523205" iyz="-0.000003085" izz="0.000256996"/>
    </inertial>
  </link>
  <link name="lh_mcp_joint">
    <visual>
      <origin rpy="1.6375789613220999807e-15 -1.0045650589924324925e-30 -1.7121057196142940206e-44" xyz="0.008406902261174501248 0.0077662438597169980437 0.014657354985032899908"/>
      <geometry>
        <mesh filename="./meshes/mcp_joint.stl"/>
      </geometry>
      <material name="mcp_joint_material">
        <color rgba="0.86666666666666669627 0.86666666666666669627 0.050980392156862744391 1.0"/>
      </material>
    </visual>
    <collision>
      <origin rpy="1.6375789613220999807e-15 -1.0045650589924324925e-30 -1.7121057196142940206e-44" xyz="0.008406902261174501248 0.0077662438597169980437 0.014657354985032899908"/>
      <geometry>
        <mesh filename="./meshes/mcp_joint.stl"/>
      </geometry>
    </collision>
    <inertial>
      <origin rpy="0 0 0" xyz="0 0 0"/>
      <mass value="0.044"/>
      <inertia ixx="0.000011499" ixy="0.000003049" ixz="0.000000121" iyy="0.000007796" iyz="0.000000112" izz="0.000014759"/>
    </inertial>
  </link>
  <link name="lh_pip">
    <visual>
      <origin rpy="-1.570796326794896558 -1.570796326794896336 0" xyz="0.0096433630922713314826 0.00029999999999999471534 0.00078403401041737472155"/>
      <geometry>
        <mesh filename="./meshes/pip.stl"/>
      </geometry>
      <material name="pip_material">
        <color rgba="0.74901960784313725839 0.74901960784313725839 0.74901960784313725839 1.0"/>
      </material>
    </visual>
    <collision>
      <origin rpy="-1.570796326794896558 -1.570796326794896336 0" xyz="0.0096433630922713314826 0.00029999999999999471534 0.00078403401041737472155"/>
      <geometry>
        <mesh filename="./meshes/pip.stl"/>
      </geometry>
    </collision>
    <inertial>
      <origin rpy="0 0 0" xyz="0 0 0"/>
      <mass value="0.032"/>
      <inertia ixx="0.000004798" ixy="0.000000012" ixz="0.000000004" iyy="0.000002862" iyz="0.000000011" izz="0.000004234"/>
    </inertial>
  </link>
  <link name="lh_dip">
    <visual>
      <origin rpy="-3.141592653589793116 4.5075111242164408299e-32 4.4395481053923607589e-32" xyz="0.021133352895225002849 -0.0084321191467048722812 0.0097850881620952234741"/>
      <geometry>
        <mesh filename="./meshes/dip.stl"/>
      </geometry>
      <material name="dip_material">
        <color rgba="0.86666666666666669627 0.86666666666666669627 0.050980392156862744391 1.0"/>
      </material>
    </visual>
    <collision>
      <origin rpy="-3.141592653589793116 4.5075111242164408299e-32 4.4395481053923607589e-32" xyz="0.021133352895225002849 -0.0084321191467048722812 0.0097850881620952234741"/>
      <geometry>
        <mesh filename="./meshes/dip.stl"/>
      </geometry>
    </collision>
    <inertial>
      <origin rpy="0 0 0" xyz="0 0 0"/>
      <mass value="0.037"/>
      <inertia ixx="0.000005542" ixy="-0.000000607" ixz="-0.000000017" iyy="0.000005727" iyz="-0.000000023" izz="0.000006682"/>
    </inertial>
  </link>
  <link name="lh_fingertip_base">
    <visual>
      <origin rpy="3.141592653589793116 1.1993117970061734707e-33 4.4395481053923607589e-32" xyz="0.013286424108533503169 -0.0061142383865419869249 0.014499999999999497666"/>
      <geometry>
        <mesh filename="./meshes/fingertip_base.stl"/>
      </geometry>
      <material name="fingertip_material">
        <color rgba="0.86666666666666669627 0.86666666666666669627 0.050980392156862744391 1.0"/>
      </material>
    </visual>
    <collision>
      <origin rpy="3.141592653589793116 1.1993117970061734707e-33 4.4395481053923607589e-32" xyz="0.013286424108533503169 -0.0061142383865419869249 0.014499999999999497666"/>
      <geometry>
        <mesh filename="./meshes/fingertip_base.stl"/>
      </geometry>
    </collision>
    <inertial>
      <origin rpy="0 0 0" xyz="0 0 0"/>
      <mass value="0.016"/>
      <inertia ixx="0.000003368" ixy="0.000000115" ixz="0" iyy="0.000001556" iyz="0" izz="0.000002863"/>
    </inertial>
  </link>
  <joint name="lh_joint_0" type="revolute">
    <origin rpy="-1.57079632679489678 2.8029314871654157891e-15 1.570796326794896336" xyz="-0.012200000000000005979 0.038100000000000001921 0.014499999999999985123"/>
    <parent link="lh_mcp_joint"/>
    <child link="lh_pip"/>
    <axis xyz="0 0 -1"/>
    <limit effort="0.95" lower="-1.047" upper="1.047" velocity="8.48"/>
    <joint_properties friction="0.0"/>
  </joint>
  <joint name="lh_joint_1" type="revolute">
    <origin rpy="1.5707963267948987784 1.570796326794896558 0" xyz="-0.082574224938392518092 -0.085740011501137525229 0.0078008885838987494094"/>
    <parent link="lh_palm_lower_left"/>
    <child link="lh_mcp_joint"/>
    <axis xyz="0 0 -1"/>
    <limit effort="0.95" lower="-0.314" upper="2.23" velocity="8.48"/>
    <joint_properties friction="0.0"/>
  </joint>
  <joint name="lh_joint_2" type="revolute">
    <origin rpy="1.5707963267948958919 -1.570796326794896336 0" xyz="0.014999999999999961281 0.014299999999999993272 -0.013000000000000025424"/>
    <parent link="lh_pip"/>
    <child link="lh_dip"/>
    <axis xyz="0 0 -1"/>
    <limit effort="0.95" lower="-0.506" upper="1.885" velocity="8.48"/>
    <joint_properties friction="0.0"/>
  </joint>
  <joint name="lh_joint_3" type="revolute">
    <origin rpy="4.5935029425113685044e-17 -2.8730071914463794583e-16 4.4395481053923607589e-32" xyz="-4.0880582469551840497e-09 -0.03610000421036734658 0.0002000000000000612399"/>
    <parent link="lh_dip"/>
    <child link="lh_fingertip_base"/>
    <axis xyz="0 0 -1"/>
    <limit effort="0.95" lower="-0.366" upper="2.042" velocity="8.48"/>
    <joint_properties friction="0.0"/>
  </joint>
  <link name="lh_mcp_joint_2">
    <visual>
      <origin rpy="1.6375789613220997835e-15 -1.0045650589925207743e-30 -1.2404717968013979433e-44" xyz="0.008406902261174501248 0.0077662438597169841659 0.014657354985032906847"/>
      <geometry>
        <mesh filename="./meshes/mcp_joint.stl"/>
      </geometry>
      <material name="mcp_joint_material">
        <color rgba="0.86666666666666669627 0.86666666666666669627 0.050980392156862744391 1.0"/>
      </material>
    </visual>
    <collision>
      <origin rpy="1.6375789613220997835e-15 -1.0045650589925207743e-30 -1.2404717968013979433e-44" xyz="0.008406902261174501248 0.0077662438597169841659 0.014657354985032906847"/>
      <geometry>
        <mesh filename="./meshes/mcp_joint.stl"/>
      </geometry>
    </collision>
    <inertial>
      <origin rpy="0 0 0" xyz="0 0 0"/>
      <mass value="0.044"/>
      <inertia ixx="0.000011499" ixy="0.000003049" ixz="0.000000121" iyy="0.000007796" iyz="0.000000112" izz="0.000014759"/>
    </inertial>
  </link>
  <link name="lh_pip_2">
    <visual>
      <origin rpy="-1.570796326794896558 -1.570796326794896336 0" xyz="0.0096433630922713314826 0.00029999999999998777644 0.00078403401041737472155"/>
      <geometry>
        <mesh filename="./meshes/pip.stl"/>
      </geometry>
      <material name="pip_material">
        <color rgba="0.74901960784313725839 0.74901960784313725839 0.74901960784313725839 1.0"/>
      </material>
    </visual>
    <collision>
      <origin rpy="-1.570796326794896558 -1.570796326794896336 0" xyz="0.0096433630922713314826 0.00029999999999998777644 0.00078403401041737472155"/>
      <geometry>
        <mesh filename="./meshes/pip.stl"/>
      </geometry>
    </collision>
    <inertial>
      <origin rpy="0 0 0" xyz="0 0 0"/>
      <mass value="0.032"/>
      <inertia ixx="0.000004798" ixy="0.000000012" ixz="0.000000004" iyy="0.000002862" iyz="0.000000011" izz="0.000004234"/>
    </inertial>
  </link>
  <link name="lh_dip_2">
    <visual>
      <origin rpy="-3.141592653589793116 2.1146933785271955805e-32 1.4408183216511868558e-31" xyz="0.021133352895225002849 -0.0084321191467048722812 0.0097850881620952373519"/>
      <geometry>
        <mesh filename="./meshes/dip.stl"/>
      </geometry>
      <material name="dip_material">
        <color rgba="0.86666666666666669627 0.86666666666666669627 0.050980392156862744391 1.0"/>
      </material>
    </visual>
    <collision>
      <origin rpy="-3.141592653589793116 2.1146933785271955805e-32 1.4408183216511868558e-31" xyz="0.021133352895225002849 -0.0084321191467048722812 0.0097850881620952373519"/>
      <geometry>
        <mesh filename="./meshes/dip.stl"/>
      </geometry>
    </collision>
    <inertial>
      <origin rpy="0 0 0" xyz="0 0 0"/>
      <mass value="0.037"/>
      <inertia ixx="0.000005542" ixy="-0.000000607" ixz="-0.000000017" iyy="0.000005727" iyz="-0.000000023" izz="0.000006682"/>
    </inertial>
  </link>
  <link name="lh_fingertip_base_2">
    <visual>
      <origin rpy="3.141592653589793116 1.1993117970061734707e-33 4.4395481053923607589e-32" xyz="0.013286424108533503169 -0.0061142383865419869249 0.014499999999999497666"/>
      <geometry>
        <mesh filename="./meshes/fingertip_base.stl"/>
      </geometry>
      <material name="fingertip_material">
        <color rgba="0.86666666666666669627 0.86666666666666669627 0.050980392156862744391 1.0"/>
      </material>
    </visual>
    <collision>
      <origin rpy="3.141592653589793116 1.1993117970061734707e-33 4.4395481053923607589e-32" xyz="0.013286424108533503169 -0.0061142383865419869249 0.014499999999999497666"/>
      <geometry>
        <mesh filename="./meshes/fingertip_base.stl"/>
      </geometry>
    </collision>
    <inertial>
      <origin rpy="0 0 0" xyz="0 0 0"/>
      <mass value="0.016"/>
      <inertia ixx="0.000003368" ixy="0.000000115" ixz="0" iyy="0.000001556" iyz="0" izz="0.000002863"/>
    </inertial>
  </link>
  <joint name="lh_joint_4" type="revolute">
    <origin rpy="-1.570796326794896558 1.6094417208041279902e-15 1.5707963267948943376" xyz="-0.012200000000000002509 0.038099999999999988043 0.014499999999999999001"/>
    <parent link="lh_mcp_joint_2"/>
    <child link="lh_pip_2"/>
    <axis xyz="0 0 -1"/>
    <limit effort="0.95" lower="-1.047" upper="1.047" velocity="8.48"/>
    <joint_properties friction="0.0"/>
  </joint>
  <joint name="lh_joint_5" type="revolute">
    <origin rpy="1.5707963267948992225 1.570796326794896558 0" xyz="-0.08257422493900856697 -0.040290011501137479311 0.007800888583679612201"/>
    <parent link="lh_palm_lower_left"/>
    <child link="lh_mcp_joint_2"/>
    <axis xyz="0 0 -1"/>
    <limit effort="0.95" lower="-0.314" upper="2.23" velocity="8.48"/>
    <joint_properties friction="0.0"/>
  </joint>
  <joint name="lh_joint_6" type="revolute">
    <origin rpy="1.5707963267948958919 -1.570796326794896336 0" xyz="0.01499999999999996475 0.014299999999999986333 -0.013000000000000025424"/>
    <parent link="lh_pip_2"/>
    <child link="lh_dip_2"/>
    <axis xyz="0 0 -1"/>
    <limit effort="0.95" lower="-0.506" upper="1.885" velocity="8.48"/>
    <joint_properties friction="0.0"/>
  </joint>
  <joint name="lh_joint_7" type="revolute">
    <origin rpy="4.5935029425113654229e-17 -2.8730071914463794583e-16 1.4408183216511868558e-31" xyz="1.0408340855860842566e-16 -0.036099999999999875244 0.00020000000000007511769"/>
    <parent link="lh_dip_2"/>
    <child link="lh_fingertip_base_2"/>
    <axis xyz="0 0 -1"/>
    <limit effort="0.95" lower="-0.366" upper="2.042" velocity="8.48"/>
    <joint_properties friction="0.0"/>
  </joint>
  <link name="lh_mcp_joint_3">
    <visual>
      <origin rpy="1.6375789613220999807e-15 -1.0045650589924056927e-30 -1.6748666234615871922e-44" xyz="0.008406902261174501248 0.0077662438597169980437 0.014657354985032912051"/>
      <geometry>
        <mesh filename="./meshes/mcp_joint.stl"/>
      </geometry>
      <material name="mcp_joint_material">
        <color rgba="0.86666666666666669627 0.86666666666666669627 0.050980392156862744391 1.0"/>
      </material>
    </visual>
    <collision>
      <origin rpy="1.6375789613220999807e-15 -1.0045650589924056927e-30 -1.6748666234615871922e-44" xyz="0.008406902261174501248 0.0077662438597169980437 0.014657354985032912051"/>
      <geometry>
        <mesh filename="./meshes/mcp_joint.stl"/>
      </geometry>
    </collision>
    <inertial>
      <origin rpy="0 0 0" xyz="0 0 0"/>
      <mass value="0.044"/>
      <inertia ixx="0.000011499" ixy="0.000003049" ixz="0.000000121" iyy="0.000007796" iyz="0.000000112" izz="0.000014759"/>
    </inertial>
  </link>
  <link name="lh_pip_3">
    <visual>
      <origin rpy="-1.570796326794896558 -1.570796326794896336 0" xyz="0.0096433630922713314826 0.00029999999999999124589 0.00078403401041737472155"/>
      <geometry>
        <mesh filename="./meshes/pip.stl"/>
      </geometry>
      <material name="pip_material">
        <color rgba="0.74901960784313725839 0.74901960784313725839 0.74901960784313725839 1.0"/>
      </material>
    </visual>
    <collision>
      <origin rpy="-1.570796326794896558 -1.570796326794896336 0" xyz="0.0096433630922713314826 0.00029999999999999124589 0.00078403401041737472155"/>
      <geometry>
        <mesh filename="./meshes/pip.stl"/>
      </geometry>
    </collision>
    <inertial>
      <origin rpy="0 0 0" xyz="0 0 0"/>
      <mass value="0.032"/>
      <inertia ixx="0.000004798" ixy="0.000000012" ixz="0.000000004" iyy="0.000002862" iyz="0.000000011" izz="0.000004234"/>
    </inertial>
  </link>
  <link name="lh_dip_3">
    <visual>
      <origin rpy="-3.141592653589793116 -1.4095651113919093005e-33 1.5565411607615035382e-32" xyz="0.021133352895225006318 -0.0084321191467048688117 0.0097850881620952408213"/>
      <geometry>
        <mesh filename="./meshes/dip.stl"/>
      </geometry>
      <material name="dip_material">
        <color rgba="0.86666666666666669627 0.86666666666666669627 0.050980392156862744391 1.0"/>
      </material>
    </visual>
    <collision>
      <origin rpy="-3.141592653589793116 -1.4095651113919093005e-33 1.5565411607615035382e-32" xyz="0.021133352895225006318 -0.0084321191467048688117 0.0097850881620952408213"/>
      <geometry>
        <mesh filename="./meshes/dip.stl"/>
      </geometry>
    </collision>
    <inertial>
      <origin rpy="0 0 0" xyz="0 0 0"/>
      <mass value="0.037"/>
      <inertia ixx="0.000005542" ixy="-0.000000607" ixz="-0.000000017" iyy="0.000005727" iyz="-0.000000023" izz="0.000006682"/>
    </inertial>
  </link>
  <link name="lh_fingertip_base_3">
    <visual>
      <origin rpy="3.141592653589793116 1.1993117970061734707e-33 4.4395481053923607589e-32" xyz="0.013286424108533503169 -0.0061142383865419869249 0.014499999999999497666"/>
      <geometry>
        <mesh filename="./meshes/fingertip_base.stl"/>
      </geometry>
      <material name="fingertip_material">
        <color rgba="0.86666666666666669627 0.86666666666666669627 0.050980392156862744391 1.0"/>
      </material>
    </visual>
    <collision>
      <origin rpy="3.141592653589793116 1.1993117970061734707e-33 4.4395481053923607589e-32" xyz="0.013286424108533503169 -0.0061142383865419869249 0.014499999999999497666"/>
      <geometry>
        <mesh filename="./meshes/fingertip_base.stl"/>
      </geometry>
      <material name="fingertip_material">
        <color rgba="0.86666666666666669627 0.86666666666666669627 0.050980392156862744391 1.0"/>
      </material>
    </collision>
    <inertial>
      <origin rpy="0 0 0" xyz="0 0 0"/>
      <mass value="0.016"/>
      <inertia ixx="0.000003368" ixy="0.000000115" ixz="0" iyy="0.000001556" iyz="0" izz="0.000002863"/>
    </inertial>
  </link>
  <joint name="lh_joint_8" type="revolute">
    <origin rpy="-1.57079632679489678 2.8029314871654240721e-15 1.570796326794896336" xyz="-0.012200000000000002509 0.038100000000000001921 0.01450000000000000247"/>
    <parent link="lh_mcp_joint_3"/>
    <child link="lh_pip_3"/>
    <axis xyz="0 0 -1"/>
    <limit effort="0.95" lower="-1.047" upper="1.047" velocity="8.48"/>
    <joint_properties friction="0.0"/>
  </joint>
  <joint name="lh_joint_9" type="revolute">
    <origin rpy="1.5707963267948987784 1.570796326794896558 0" xyz="-0.082574224938392323803 0.0051599884988625839555 0.0078008885838987598177"/>
    <parent link="lh_palm_lower_left"/>
    <child link="lh_mcp_joint_3"/>
    <axis xyz="0 0 -1"/>
    <limit effort="0.95" lower="-0.314" upper="2.23" velocity="8.48"/>
    <joint_properties friction="0.0"/>
  </joint>
  <joint name="lh_joint_10" type="revolute">
    <origin rpy="1.5707963267948958919 -1.570796326794896336 0" xyz="0.01499999999999996822 0.014299999999999989803 -0.013000000000000025424"/>
    <parent link="lh_pip_3"/>
    <child link="lh_dip_3"/>
    <axis xyz="0 0 -1"/>
    <limit effort="0.95" lower="-0.506" upper="1.885" velocity="8.48"/>
    <joint_properties friction="0.0"/>
  </joint>
  <joint name="lh_joint_11" type="revolute">
    <origin rpy="4.5935029425113685044e-17 -2.8730071914463799514e-16 1.5565411607615035382e-32" xyz="1.0234868508263161857e-16 -0.036099999999999868305 0.00020000000000007858714"/>
    <parent link="lh_dip_3"/>
    <child link="lh_fingertip_base_3"/>
    <axis xyz="0 0 -1"/>
    <limit effort="0.95" lower="-0.366" upper="2.042" velocity="8.48"/>
    <joint_properties friction="0.0"/>
  </joint>
  <link name="lh_pip_4">
    <visual>
      <origin rpy="1.570796326794896558 -7.3390819752428127848e-33 -2.4651903288114908395e-32" xyz="0.043932212010113096123 0.0068107072931437306895 0.021460907869434775463"/>
      <geometry>
        <mesh filename="./meshes/thumb_left_temp_base.stl"/>
      </geometry>
      <material name="thumb_left_temp_base_material">
        <color rgba="0.74901960784313725839 0.74901960784313725839 0.74901960784313725839 1.0"/>
      </material>
    </visual>
    <collision>
      <origin rpy="1.570796326794896558 -7.3390819752428127848e-33 -2.4651903288114908395e-32" xyz="0.043932212010113096123 0.0068107072931437306895 0.021460907869434775463"/>
      <geometry>
        <mesh filename="./meshes/thumb_left_temp_base.stl"/>
      </geometry>
    </collision>
    <inertial>
      <origin rpy="0 0 0" xyz="0 0 0"/>
      <mass value="0.032"/>
      <inertia ixx="0.000004798" ixy="0.000000012" ixz="0.000000004" iyy="0.000002862" iyz="0.000000011" izz="0.000004234"/>
    </inertial>
  </link>
  <link name="lh_thumb_pip">
    <visual>
      <origin rpy="1.570796326794896558 1.6544612350564779759e-32 0" xyz="0.011961920770611200737 -5.3169274538689137444e-16 -0.015852648956664189273"/>
      <geometry>
        <mesh filename="./meshes/thumb_pip.stl"/>
      </geometry>
      <material name="thumb_pip_material">
        <color rgba="0.86666666666666669627 0.86666666666666669627 0.050980392156862744391 1.0"/>
      </material>
    </visual>
    <collision>
      <origin rpy="1.570796326794896558 1.6544612350564779759e-32 0" xyz="0.011961920770611200737 -5.3169274538689137444e-16 -0.015852648956664189273"/>
      <geometry>
        <mesh filename="./meshes/thumb_pip.stl"/>
      </geometry>
    </collision>
    <inertial>
      <origin rpy="0 0 0" xyz="0 0 0"/>
      <mass value="0.003"/>
      <inertia ixx="0.000000593" ixy="0" ixz="0" iyy="0.000000549" iyz="0" izz="0.000000224"/>
    </inertial>
  </link>
  <link name="lh_thumb_dip">
    <visual>
      <origin rpy="1.9428902930940096476e-16 3.2751579226442204717e-15 -2.172448977268026949e-31" xyz="0.043968715707239161561 0.057952952973709212503 -0.0086286764493694757122"/>
      <geometry>
        <mesh filename="./meshes/thumb_dip.stl"/>
      </geometry>
      <material name="thumb_dip_material">
        <color rgba="0.86666666666666669627 0.86666666666666669627 0.050980392156862744391 1.0"/>
      </material>
    </visual>
    <collision>
      <origin rpy="1.9428902930940096476e-16 3.2751579226442204717e-15 -2.172448977268026949e-31" xyz="0.043968715707239161561 0.057952952973709212503 -0.0086286764493694757122"/>
      <geometry>
        <mesh filename="./meshes/thumb_dip.stl"/>
      </geometry>
    </collision>
    <inertial>
      <origin rpy="0 0 0" xyz="0 0 0"/>
      <mass value="0.038"/>
      <inertia ixx="0.000008474" ixy="0.000000241" ixz="0.000000026" iyy="0.000003841" iyz="0.000000025" izz="0.000007679"/>
    </inertial>
  </link>
  <link name="lh_thumb_fingertip_base">
    <visual>
      <origin rpy="4.3790577010156367543e-47 -3.3306690738754701143e-16 1.2042408677791935383e-46" xyz="0.062559538462667388381 0.078459682911396988469 0.048992911807332215068"/>
      <geometry>
        <mesh filename="./meshes/thumb_fingertip_base.stl"/>
      </geometry>
      <material name="thumb_fingertip_material">
        <color rgba="0.60392156862745094426 0.14901960784313725283 0.14901960784313725283 1.0"/>
      </material>
    </visual>
    <collision>
      <origin rpy="4.3790577010156367543e-47 -3.3306690738754701143e-16 1.2042408677791935383e-46" xyz="0.062559538462667388381 0.078459682911396988469 0.048992911807332215068"/>
      <geometry>
        <mesh filename="./meshes/thumb_fingertip_base.stl"/>
      </geometry>
    </collision>
    <inertial>
      <origin rpy="0 0 0" xyz="0 0 0"/>
      <mass value="0.049"/>
      <inertia ixx="0.000020372" ixy="-0.000000489" ixz="-0.00000003" iyy="0.000004336" iyz="-0.000000097" izz="0.000019845"/>
    </inertial>
  </link>
  <joint name="lh_joint_12" type="revolute">
    <origin rpy="3.5629789726327258012e-15 1.5707963267948961139 0" xyz="-0.14487422493839263726 -0.090040011501137440231 0.004900888583899039308"/>
    <parent link="lh_palm_lower_left"/>
    <child link="lh_pip_4"/>
    <axis xyz="0 0 -1"/>
    <limit effort="0.95" lower="-2.443" upper="0.47" velocity="8.48"/>
    <joint_properties friction="0.0"/>
  </joint>
  <joint name="lh_joint_13" type="revolute">
    <origin rpy="-1.570796326794896336 -1.570796326794896336 0" xyz="-1.0148132334464321502e-16 -0.014100000000000126321 -0.012999999999999956035"/>
    <parent link="lh_pip_4"/>
    <child link="lh_thumb_pip"/>
    <axis xyz="0 0 -1"/>
    <limit effort="0.95" lower="-2.094" upper="0.349" velocity="8.48"/>
    <joint_properties friction="0.0"/>
  </joint>
  <joint name="lh_joint_14" type="revolute">
    <origin rpy="-1.570796326794896558 -1.5671206742950610653e-15 -5.6898930012051145053e-16" xyz="0 0.014499999999999967776 -0.017000000000000042855"/>
    <parent link="lh_thumb_pip"/>
    <child link="lh_thumb_dip"/>
    <axis xyz="0 0 -1"/>
    <limit effort="0.95" lower="-1.20" upper="1.90" velocity="8.48"/>
    <joint_properties friction="0.0"/>
  </joint>
  <joint name="lh_joint_15" type="revolute">
    <origin rpy="-3.1092019091748562186e-17 -4.9644253794601335075e-16 -3.1415926535897846783" xyz="-1.1102230246251565404e-16 0.046599999999999683342 0.00020000000000065451533"/>
    <parent link="lh_thumb_dip"/>
    <child link="lh_thumb_fingertip_base"/>
    <axis xyz="0 0 -1"/>
    <limit effort="0.95" lower="-1.34" upper="1.88" velocity="8.48"/>
    <joint_properties friction="0.0"/>
  </joint>
  <link name="lh_wrist"/>
  <joint name="lh_palm_to_wrist" type="fixed">
    <origin rpy="0 1.5707963267948966 0" xyz="-0.16 -0.04 -0.01"/>
    <parent link="lh_palm_lower_left"/>
    <child link="lh_wrist"/>
  </joint>
  <link name="lh_palm_lower"/>
  <joint name="lh_palm_lower_to_palm_lower_left" type="fixed">
    <origin rpy="0 0 0" xyz="0.07547898  0.09179777 -0.02652329"/>
    <parent link="lh_palm_lower"/>
    <child link="lh_palm_lower_left"/>
  </joint>
  <!-- the links and joints for customized fingertips -->
  <link name="lh_fingertip_1">
    <visual>
      <origin rpy="0 0 0" xyz="0 0 0"/>
      <geometry>
        <mesh filename="./meshes/convex_tip_v2.obj"/>
      </geometry>
      <material name="fingertip_material">
        <color rgba="0.86666666666666669627 0.86666666666666669627 0.050980392156862744391 1.0"/>
      </material>
    </visual>
    <collision>
      <origin rpy="0 0 0" xyz="0 0 0"/>
      <geometry>
        <mesh filename="./meshes/convex_tip_v2.obj"/>
      </geometry>
    </collision>
    <inertial>
      <!-- TODO(yongpeng) modify the inertia -->
      <origin rpy="0 0 0" xyz="0 0 0"/>
      <mass value="0.0000000001"/>
      <inertia ixx="0.0000000001" ixy="0" ixz="0" iyy="0.0000000001" iyz="0" izz="0.0000000001"/>
    </inertial>
  </link>
  <link name="lh_fingertip_2">
    <visual>
      <origin rpy="0 0 0" xyz="0 0 0"/>
      <geometry>
        <mesh filename="./meshes/convex_tip_v2.obj"/>
      </geometry>
      <material name="fingertip_material">
        <color rgba="0.86666666666666669627 0.86666666666666669627 0.050980392156862744391 1.0"/>
      </material>
    </visual>
    <collision>
      <origin rpy="0 0 0" xyz="0 0 0"/>
      <geometry>
        <mesh filename="./meshes/convex_tip_v2.obj"/>
      </geometry>
    </collision>
    <inertial>
      <!-- TODO(yongpeng) modify the inertia -->
      <origin rpy="0 0 0" xyz="0 0 0"/>
      <mass value="0.0000000001"/>
      <inertia ixx="0.0000000001" ixy="0" ixz="0" iyy="0.0000000001" iyz="0" izz="0.0000000001"/>
    </inertial>
  </link>
  <link name="lh_fingertip_3">
    <visual>
      <origin rpy="0 0 0" xyz="0 0 0"/>
      <geometry>
        <mesh filename="./meshes/convex_tip_v2.obj"/>
      </geometry>
      <material name="fingertip_material">
        <color rgba="0.86666666666666669627 0.86666666666666669627 0.050980392156862744391 1.0"/>
      </material>
    </visual>
    <collision>
      <origin rpy="0 0 0" xyz="0 0 0"/>
      <geometry>
        <mesh filename="./meshes/convex_tip_v2.obj"/>
      </geometry>
    </collision>
    <inertial>
      <!-- TODO(yongpeng) modify the inertia -->
      <origin rpy="0 0 0" xyz="0 0 0"/>
      <mass value="0.0000000001"/>
      <inertia ixx="0.0000000001" ixy="0" ixz="0" iyy="0.0000000001" iyz="0" izz="0.0000000001"/>
    </inertial>
  </link>
  <link name="lh_thumb_fingertip">
    <visual>
      <origin rpy="0 0 0" xyz="0 0 0"/>
      <geometry>
        <mesh filename="./meshes/convex_tip_thumb_v2.obj"/>
      </geometry>
      <material name="fingertip_material">
        <color rgba="0.86666666666666669627 0.86666666666666669627 0.050980392156862744391 1.0"/>
      </material>
    </visual>
    <collision>
      <origin rpy="0 0 0" xyz="0 0 0"/>
      <geometry>
        <mesh filename="./meshes/convex_tip_thumb_v2.obj"/>
      </geometry>
    </collision>
    <inertial>
      <origin rpy="0 0 0" xyz="0 0 0"/>
      <mass value="0.0000000001"/>
      <inertia ixx="0.0000000001" ixy="0" ixz="0" iyy="0.0000000001" iyz="0" izz="0.0000000001"/>
    </inertial>
  </link>
  <joint name="lh_finger1_tipbase2tip" type="fixed">
    <origin rpy="0 1.5707963267948966 3.141592653589793" xyz="0 -0.017 0.0145"/>
    <parent link="lh_fingertip_base"/>
    <child link="lh_fingertip_1"/>
  </joint>
  <joint name="lh_finger2_tipbase2tip" type="fixed">
    <origin rpy="0 1.5707963267948966 3.141592653589793" xyz="0 -0.017 0.0145"/>
    <parent link="lh_fingertip_base_2"/>
    <child link="lh_fingertip_2"/>
  </joint>
  <joint name="lh_finger3_tipbase2tip" type="fixed">
    <origin rpy="0 1.5707963267948966 3.141592653589793" xyz="0 -0.017 0.0145"/>
    <parent link="lh_fingertip_base_3"/>
    <child link="lh_fingertip_3"/>
  </joint>
  <joint name="lh_thumb_tipbase2tip" type="fixed">
    <origin rpy="0 1.5707963267948966 3.141592653589793" xyz="0 -0.03 -0.0145"/>
    <parent link="lh_thumb_fingertip_base"/>
    <child link="lh_thumb_fingertip"/>
  </joint>
  <!-- the links and joints for fingertip centers -->
  <link name="lh_finger1_tip_center"/>
  <link name="lh_finger2_tip_center"/>
  <link name="lh_finger3_tip_center"/>
  <link name="lh_thumb_tip_center"/>
  <joint name="lh_finger1_tip2center" type="fixed">
    <origin rpy="0 0 1.5707963267948966" xyz="0 0.025 0.01"/>
    <parent link="lh_fingertip_1"/>
    <child link="lh_finger1_tip_center"/>
  </joint>
  <joint name="lh_finger2_tip2center" type="fixed">
    <origin rpy="0 0 1.5707963267948966" xyz="0 0.025 0.01"/>
    <parent link="lh_fingertip_2"/>
    <child link="lh_finger2_tip_center"/>
  </joint>
  <joint name="lh_finger3_tip2center" type="fixed">
    <origin rpy="0 0 1.5707963267948966" xyz="0 0.025 0.01"/>
    <parent link="lh_fingertip_3"/>
    <child link="lh_finger3_tip_center"/>
  </joint>
  <joint name="lh_thumb_tip2center" type="fixed">
    <origin rpy="0 0 1.5707963267948966" xyz="0 0.0245 0.011"/>
    <parent link="lh_thumb_fingertip"/>
    <child link="lh_thumb_tip_center"/>
  </joint>
  <!-- the links and joints for fingertip centers (lower) -->
  <!-- 0.02 m is the length of human distal link -->
  <link name="lh_finger1_tip_center_lower"/>
  <link name="lh_finger2_tip_center_lower"/>
  <link name="lh_finger3_tip_center_lower"/>
  <link name="lh_thumb_tip_center_lower"/>
  <joint name="lh_finger1_tip_center2lower" type="fixed">
    <origin rpy="0 0 0" xyz="-0.02 0 0"/>
    <parent link="lh_finger1_tip_center"/>
    <child link="lh_finger1_tip_center_lower"/>
  </joint>
  <joint name="lh_finger2_tip_center2lower" type="fixed">
    <origin rpy="0 0 0" xyz="-0.02 0 0"/>
    <parent link="lh_finger2_tip_center"/>
    <child link="lh_finger2_tip_center_lower"/>
  </joint>
  <joint name="lh_finger3_tip_center2lower" type="fixed">
    <origin rpy="0 0 0" xyz="-0.02 0 0"/>
    <parent link="lh_finger3_tip_center"/>
    <child link="lh_finger3_tip_center_lower"/>
  </joint>
  <joint name="lh_thumb_tip_center2lower" type="fixed">
    <origin rpy="0 0 0" xyz="-0.02 0 0"/>
    <parent link="lh_thumb_tip_center"/>
    <child link="lh_thumb_tip_center_lower"/>
  </joint>
  <joint name="rah_joint" type="fixed">
    <origin rpy="0 0 0" xyz="0 0 0.034"/>
    <parent link="ra_RotZB"/>
    <child link="rh_palm_lower"/>
  </joint>
  <joint name="lah_joint" type="fixed">
    <origin rpy="0 0 0" xyz="0 0 0.034"/>
    <parent link="la_RotZB"/>
    <child link="lh_palm_lower"/>
  </joint>
  <!-- world frame -->
  <link name="world"/>
  <joint name="ra_world_joint" type="fixed">
    <origin rpy="0 0 0" xyz="0 -0.2 0"/>
    <parent link="world"/>
    <child link="ra_base"/>
  </joint>
  <joint name="la_world_joint" type="fixed">
    <origin rpy="0 0 0" xyz="0 0.2 0"/>
    <parent link="world"/>
    <child link="la_base"/>
  </joint>
</robot>
